Workbook

Sheet ECTS
A1: TRENUTNO STANJE
A2: https://github.com/APapratt13/Academic_Weapon/tree/master | B2: <-- link | H2: UKUPNO: | I2: =SUM(F4,F9, G15, O15) -> 55
A3: #1 SEMESTAR
A4: DIGLOG | B4: UPRO | C4: LINALG | D4: MATAN | E4: VJEKOM | F4: =SUM(A5:E5) -> 25
A5: =IF(SUM(A6:A7)>0,6,0) -> 6 | B5: =IF(SUM(B6:B7)>0,7,0) -> 7 | C5: =IF(SUM(C6:C7)>0,5,0) -> 0 | D5: =IF(SUM(D6:D7)>0,8,0) -> 8 | E5: =IF(SUM(E6:E7)>0,4,0) -> 4
A6: =IF('SEM1'!E7 >1, 1, 0) -> 1 | B6: =IF('SEM1'!E13 >1, 1, 0) -> 1 | C6: =IF('SEM1'!E19 >1, 1, 0) -> 0 | D6: =IF('SEM1'!E25 >1, 1, 0) -> 1 | E6: =IF('SEM1'!E36 >1, 1, 0) -> 1
A7: =IF(SEM1_rokovi!E4 >1, 1, 0) -> 0 | B7: =IF(SEM1_rokovi!E9 >1, 1, 0) -> 0 | C7: =IF(SEM1_rokovi!E12 >1, 1, 0) -> 0 | D7: =IF(SEM1_rokovi!E15 >1, 1, 0) -> 0 | E7: =IF(SEM1_rokovi!E22 >1, 1, 0) -> 0
A8: #2 SEMESTAR
A9: FIZ | B9: OOP | C9: OE | D9: MATAN2 | E9: PITI | F9: =SUM(A10:E10) -> 30
A10: =IF(SUM(A11:A12)>0,6,0) -> 6 | B10: =IF(SUM(B11:B12)>0,8,0) -> 8 | C10: =IF(SUM(C11:C12)>0,7,0) -> 7 | D10: =IF(SUM(D11:D12)>0,7,0) -> 7 | E10: =IF(SUM(E11:E12)>0,2,0) -> 2
A11: =IF('SEM2'!E7 >1, 1, 0) -> 0 | B11: =IF('SEM2'!E14 >1, 1, 0) -> 1 | C11: =IF('SEM2'!E24 >1, 1, 0) -> 0 | D11: =IF('SEM2'!E30 >1, 1, 0) -> 0 | E11: =IF('SEM2'!E35 >1, 1, 0) -> 1
A12: =IF(SEM2_rokovi!E6 >1, 1, 0) -> 1 | B12: =IF(SEM2_rokovi!E9 >1, 1, 0) -> 0 | C12: =IF(SEM2_rokovi!E18 >1, 1, 0) -> 1 | D12: =IF(SEM2_rokovi!E21 >1, 1, 0) -> 1 | E12: =IF(SEM2_rokovi!E24 >1, 1, 0) -> 0
A14: #3_E SEMESTAR | I14: #3_R SEMESTAR
A15: ELE1 | B15: ELEKRU | C15: FIZ2 | D15: MATAN2 | E15: MUELE | F15: INŽEKO | G15: =SUM(A16:E16) -> 0 | I15: VIS | J15: ASP | K15: ARH | L15: DISMAT | M15: TINF | N15: INŽEKO | O15: =SUM(I16:M16) -> 0
A16: =IF(SUM(A17:A18)>0,6,0) -> 0 | B16: =IF(SUM(B17:B18)>0,8,0) -> 0 | C16: =IF(SUM(C17:C18)>0,7,0) -> 0 | D16: =IF(SUM(D17:D18)>0,7,0) -> 0 | E16: =IF(SUM(E17:E18)>0,2,0) -> 0 | F16: =IF(SUM(F17:F18)>0,2,0) -> 0 | I16: =IF(SUM(I17:I18)>0,6,0) -> 0 | J16: =IF(SUM(J17:J18)>0,8,0) -> 0 | K16: =IF(SUM(K17:K18)>0,7,0) -> 0 | L16: =IF(SUM(L17:L18)>0,7,0) -> 0 | M16: =IF(SUM(M17:M18)>0,2,0) -> 0 | N16: =IF(SUM(N17:N18)>0,2,0) -> 0
A17: =IF(SEM3_E!E5 >1, 1, 0) -> 0 | B17: =IF(SEM3_E!E14 >1, 1, 0) -> 0 | C17: =IF(SEM3_E!E22 >1, 1, 0) -> 0 | D17: =IF(SEM3_E!E29 >1, 1, 0) -> 0 | E17: =IF(SEM3_E!E37 >1, 1, 0) -> 0 | F17: =IF(SEM3_E!E45 >1, 1, 0) -> 0 | I17: =IF(SEM3_R!E5 >1, 1, 0) -> 0 | J17: =IF(SEM3_R!E12 >1, 1, 0) -> 0 | K17: =IF(SEM3_R!E19 >1, 1, 0) -> 0 | L17: =IF(SEM3_R!E27 >1, 1, 0) -> 0 | M17: =IF(SEM3_R!E33 >1, 1, 0) -> 0 | N17: =IF(SEM3_R!E41 >1, 1, 0) -> 0
A18: =IF(SEM3_rokovi!E5 >1, 1, 0) -> 0 | B18: =IF(SEM3_rokovi!E13 >1, 1, 0) -> 0 | C18: =IF(SEM3_rokovi!E20 >1, 1, 0) -> 0 | D18: =IF(SEM3_rokovi!E25 >1, 1, 0) -> 0 | E18: =IF(SEM3_rokovi!E32 >1, 1, 0) -> 0 | F18: =IF(SEM3_rokovi!F40 >1, 1, 0) -> 0 | I18: =IF(SEM3_rokovi!M4 >1, 1, 0) -> 0 | J18: =IF(SEM3_rokovi!M11 >1, 1, 0) -> 0 | K18: =IF(SEM3_rokovi!M17 >1, 1, 0) -> 0 | L18: =IF(SEM3_rokovi!M24 >1, 1, 0) -> 0 | M18: =IF(SEM3_rokovi!M29 >1, 1, 0) -> 0 | N18: =IF(SEM3_rokovi!M37 >1, 1, 0) -> 0

Sheet SEM1
A1: DIGLOG | B1: Moji Bodovi | C1: Maximum | D1: Postotak | F1: stanje :
A2: Labos | C2: 15 | D2: =B2/C2 -> 0 | F2: =SUM(F7:F36) -> 25
A3: Zadace | C3: 10 | D3: =B3/C3 -> 0 | M3: Racunanje ocjene | N3: DIGLOG | O3: UPRO | P3: LINALG | Q3: MATAN | R3: VJEKOM
A4: KPZ | C4: 5 | D4: =B4/C4 -> 0 | M4: 1 | N4: 1 | O4: 1 | P4: 1 | Q4: 1 | R4: 1
A5: MI | C5: 30 | D5: =B5/C5 -> 0 | M5: 2 | N5: =IF($B$7 >= 50, 1, 0) -> 1 | O5: =IF($B$13 >= 50, 1, 0) -> 1 | P5: =IF($B$19 >= 45, 1, 0) -> 0 | Q5: =IF($B$25 >= 50, 1,) -> 1 | R5: =IF($B$36 >= 60, 1,) -> 1
A6: ZI | B6: 50 | C6: 40 | D6: =B6/C6 -> 1.25 | E6: Ocjena: | F6: ECTS | M6: 3 | N6: =IF($B$7 >= 62, 1, 0) -> 0 | O6: =IF($B$13 >= 62.5, 1, 0) -> 0 | P6: =IF($B$19 >= 55, 1, ) -> 0 | Q6: =IF($B$25 >= 58, 1, ) -> 0 | R6: =IF($B$36 >= 70, 1,) -> 1
A7: UKUPNO | B7: =SUM(B2:B6) -> 50 | C7: 100 | D7: =B7/C7 -> 0.5 | E7: =N9 -> 2 | F7: =IF($E$7 >1, 6, 0) -> 6 | M7: 4 | N7: =IF($B$7 >= 75, 1, 0) -> 0 | O7: =IF($B$13 >= 75, 1, 0) -> 0 | P7: =IF($B$19 >= 70, 1, 0) -> 0 | Q7: =IF($B$25 >= 72, 1, ) -> 0 | R7: =IF($B$36 >= 80, 1,) -> 1
M8: 5 | N8: =IF($B$7 >= 88, 1, 0) -> 0 | O8: =IF($B$13 >= 87.5, 1, 0) -> 0 | P8: =IF($B$19 >= 85, 1, 0) -> 0 | Q8: =IF($B$25 >= 86, 1, 0) -> 0 | R8: =IF($B$36 >= 90, 1,) -> 1
A9: UPRO | B9: Moji Bodovi | C9: Maximum | D9: Postotak | M9: zbroj | N9: =SUM(N4:N8) -> 2 | O9: =SUM(O4:O8) -> 2 | P9: =SUM(P4:P8) -> 1 | Q9: =SUM(Q4:Q8) -> 2 | R9: =SUM(R4:R8) -> 5
A10: Labos | C10: 30 | D10: =B10/C10 -> 0
A11: MI | C11: 30 | D11: =B11/C11 -> 0
A12: ZI | B12: 62 | C12: 40 | D12: =B12/C12 -> 1.55 | E12: Ocjena: | F12: ECTS
A13: UKUPNO | B13: =SUM(B10:B12) -> 62 | C13: 100 | D13: =B13/C13 -> 0.62 | E13: =O9 -> 2 | F13: =IF($E$13 >1, 7, 0) -> 7
A15: LINALG | B15: Moji Bodovi | C15: Maximum | D15: Postotak
A16: Zadaće | B16: =(0.92+0.95+0.95+1)/2 -> 1.91 | C16: 5 | D16: =B16/C16 -> 0.382
A17: MI | C17: 50 | D17: =B17/C17 -> 0
A18: ZI | C18: 50 | D18: =B18/C18 -> 0 | E18: Ocjena: | F18: ECTS
A19: UKUPNO | B19: =IF((B17+B18) >= 45,SUM(B16:B18),(B17+B18)) -> 0 | C19: 100 | D19: =B19/C19 -> 0 | E19: =P9 -> 1 | F19: =IF($E$19 >1, 5, 0) -> 0
A21: MATAN - ONE | B21: Moji Bodovi | C21: Maximum | D21: Postotak
A22: KPZ | C22: 6 | D22: =B22/C22 -> 0
A23: MI | C23: 47 | D23: =B23/C23 -> 0
A24: ZI | B24: 50 | C24: 47 | D24: =B24/C24 -> 1.0638298 | E24: Ocjena: | F24: ECTS
A25: UKUPNO | B25: =SUM(B22:B24) -> 50 | C25: 100 | D25: =B25/C25 -> 0.5 | E25: =Q9 -> 2 | F25: =IF($E$25 >1, 8, 0) -> 8
A28: VJEKOM >:( | B28: Moji Bodovi | C28: Maximum | D28: Postotak
A29: Pripreme | C29: 10 | D29: =B29/C29 -> 0
A30: Sudjelovanje | C30: 5 | D30: =B30/C30 -> 0
A31: KPZ | C31: 10 | D31: =B31/C31 -> 0
A32: Zadaće | C32: 25 | D32: =B32/C32 -> 0
A33: Projekt | C33: 30 | D33: =B33/C33 -> 0
A34: Bonus | C34: 10 | D34: =B34/C34 -> 0
A35: MI/ZI | B35: 91 | C35: 20 | D35: =B35/C35 -> 4.55 | E35: Ocjena: | F35: ECTS
A36: UKUPNO | B36: =SUM(B29:B35) -> 91 | C36: 100 | D36: =B36/C36 -> 0.91 | E36: =R9 -> 5 | F36: =IF($E$36 >1, 4, 0) -> 4

Sheet SEM1_rokovi
A1: DIGLOG | B1: Moji Bodovi | C1: Maximum | D1: Postotak | F1: stanje :
A2: Labos | B2: ='SEM1'!B2 -> 0 | C2: 15 | D2: =B2/C2 -> 0 | F2: =SUM(F4:F34) -> 0
A3: Ispit | C3: 85 | D3: =B3/C3 -> 0 | E3: Ocjena | F3: ECTS | L3: Racunanje ocjene | M3: DIGLOG | N3: UPRO | O3: LINALG | P3: MATAN | Q3: VJEKOM
A4: Ukupno | B4: =SUM(B2:B3) -> 0 | C4: 100 | D4: =B4/C4 -> 0 | E4: =M9 -> 1 | F4: =IF($E$4 >1, 6, 0) -> 0 | L4: 1 | M4: 1 | N4: 1 | O4: 1 | P4: 1 | Q4: 1
L5: 2 | M5: =IF($B$4 >= 50, 1, 0) -> 0 | N5: =IF($B$9 >= 50, 1, 0) -> 0 | O5: =IF($B$12 >= 45, 1, 0) -> 0 | P5: =IF($B$15 >= 50, 1,) -> 0 | Q5: =IF($B$23 >= 60, 1,) -> 0
A6: UPRO | B6: Moji Bodovi | C6: Maximum | D6: Postotak | L6: 3 | M6: =IF($B$4 >= 62, 1, 0) -> 0 | N6: =IF($B$9 >= 62.5, 1, 0) -> 0 | O6: =IF($B$12 >= 55, 1, ) -> 0 | P6: =IF($B$15 >= 58, 1, ) -> 0 | Q6: =IF($B$23 >= 70, 1,) -> 0
A7: Labos | B7: ='SEM1'!B10 -> 0 | C7: 30 | D7: =B7/C7 -> 0 | L7: 4 | M7: =IF($B$4 >= 75, 1, 0) -> 0 | N7: =IF($B$9 >= 75, 1, 0) -> 0 | O7: =IF($B$12>= 70, 1, 0) -> 0 | P7: =IF($B$15 >= 72, 1, ) -> 0 | Q7: =IF($B$23 >= 80, 1,) -> 0
A8: Ispit | C8: 70 | D8: =B8/C8 -> 0 | E8: Ocjena | F8: ECTS | L8: 5 | M8: =IF($B$4 >= 88, 1, 0) -> 0 | N8: =IF($B$9 >= 87.5, 1, 0) -> 0 | O8: =IF($B$12 >= 85, 1, 0) -> 0 | P8: =IF($B$15 >= 86, 1, 0) -> 0 | Q8: =IF($B$23 >= 90, 1,) -> 0
A9: Ukupno | B9: =SUM(B7:B8) -> 0 | C9: 100 | D9: =B9/C9 -> 0 | E9: =N9 -> 1 | F9: =IF($E$9 >1, 7, 0) -> 0 | L9: zbroj | M9: =SUM(M4:M8) -> 1 | N9: =SUM(N4:N8) -> 1 | O9: =SUM(O4:O8) -> 1 | P9: =SUM(P4:P8) -> 1 | Q9: =SUM(Q4:Q8) -> 1
A11: Linearna | B11: Moji Bodovi | C11: Maximum | D11: Postotak | E11: Ocjena | F11: ECTS
A12: Ispit | C12: 100 | D12: =B12/C12 -> 0 | E12: =O9 -> 1 | F12: =IF($E$12 >1, 5, 0) -> 0
A14: Matan1 | B14: Moji Bodovi | C14: Maximum | D14: Postotak | E14: Ocjena | F14: ECTS
A15: Ispit | C15: 100 | D15: =B15/C15 -> 0 | E15: =P9 -> 1 | F15: =IF($E$15 >1, 8, 0) -> 0
A17: VJEKOM | B17: Moji Bodovi | C17: Maximum | D17: Postotak
A18: Zadaće | B18: =('SEM1'!B32/25) * 40 -> 0 | C18: 40 | D18: =B18/C18 -> 0
A19: KPZ | C19: 10 | D19: =B19/C19 -> 0
A20: Projekt | B20: ='SEM1'!B33 -> 0 | C20: 30 | D20: =B20/C20 -> 0
A21: Ispit | C21: 20 | D21: =B21/C21 -> 0 | E21: Ocjena | F21: ECTS
A22: Ukupno | B22: =SUM(B17:B21) -> 0 | C22: 100 | D22: =B22/C22 -> 0 | E22: =Q9 -> 1 | F22: =IF($E$22 >1, 4, 0) -> 0

Sheet SEM2
A1: FIZIKA | B1: Moji Bodovi | C1: Maximum | D1: Postotak | F1: stanje :
A2: Labos | B2: 8 | C2: 10 | D2: =B2/C2 -> 0.8 | F2: =SUM(F7:F35) -> 10
A3: Zadace | C3: 10 | D3: =B3/C3 -> 0 | M3: Racunanje ocjene | N3: FIZ | O3: OOP | P3: OE | Q3: MATAN2 | R3: PITI
A4: MI pismeni | C4: 28 | D4: =B4/C4 -> 0 | M4: 1 | N4: 1 | O4: 1 | P4: 1 | Q4: 1 | R4: 1
A5: ZI pismeni | C5: 28 | D5: =B5/C5 -> 0 | M5: 2 | N5: =IF($B$7 >= 50, 1, 0) -> 0 | O5: =IF($B$14 >= 50, 1, 0) -> 1 | P5: =IF($B$24 >= 50, 1, 0) -> 0 | Q5: =IF($B$30 >= 50, 1,) -> 0 | R5: =IF($B$35 >= 20, 1,) -> 1
A6: ZI usmeni | C6: 24 | D6: =B6/C6 -> 0 | E6: Ocjena: | F6: ECTS | M6: 3 | N6: =IF($B$7 >= 60, 1, 0) -> 0 | O6: =IF($B$14 >= 65, 1, 0) -> 1 | P6: =IF($B$24 >= 62, 1, ) -> 0 | Q6: =IF($B$30 >= 58, 1, ) -> 0 | R6: =IF($B$35 >= 24, 1,) -> 1
A7: UKUPNO | B7: =SUM(B2:B6) -> 8 | C7: 100 | D7: =B7/C7 -> 0.08 | E7: =N9 -> 1 | F7: =IF($E$7 >1, 6, 0) -> 0 | M7: 4 | N7: =IF($B$7 >= 70, 1, 0) -> 0 | O7: =IF($B$14 >= 80, 1, 0) -> 0 | P7: =IF($B$24 >= 74, 1, 0) -> 0 | Q7: =IF($B$30 >= 72, 1, ) -> 0 | R7: =IF($B$35 >= 30, 1,) -> 0
M8: 5 | N8: =IF($B$7 >= 85, 1, 0) -> 0 | O8: =IF($B$14 >= 90, 1, 0) -> 0 | P8: =IF($B$24 >= 86, 1, 0) -> 0 | Q8: =IF($B$30 >= 86, 1, 0) -> 0 | R8: =IF($B$35 >= 36, 1,) -> 0
A9: OOP | B9: Moji Bodovi | C9: Maximum | D9: Postotak | M9: zbroj | N9: =SUM(N4:N8) -> 1 | O9: =SUM(O4:O8) -> 3 | P9: =SUM(P4:P8) -> 1 | Q9: =SUM(Q4:Q8) -> 1 | R9: =SUM(R4:R8) -> 3
A10: Labos | C10: 10 | D10: =B10/C10 -> 0
A11: KPZ | C11: 10 | D11: =B11/C11 -> 0
A12: MI | C12: 40 | D12: =B12/C12 -> 0
A13: ZI | B13: 65 | C13: 40 | D13: =B13/C13 -> 1.625 | E13: Ocjena: | F13: ECTS
A14: UKUPNO | B14: =SUM(B10:B13) -> 65 | C14: 100 | D14: =B14/C14 -> 0.65 | E14: =O9 -> 3 | F14: =IF($E$14 >1, 8, 0) -> 8
A16: OElektro | B16: Moji Bodovi | C16: Maximum | D16: Postotak
A17: Labosi | B17: 6 | C17: 6 | D17: =B17/C17 -> 1
A18: DZ | B18: 5 | C18: 5 | D18: =B18/C18 -> 1
A19: KPZ | B19: 7 | C19: 9 | D19: =B19/C19 -> 0.77777778
A20: lil extra | B20: 3 | C20: 4 | D20: =B20/C20 -> 0.75
A21: MI pismeni | C21: 26 | D21: =B21/C21 -> 0 | E21: =SUM(B21:B22)/52 -> 0
A22: ZI pismeni | C22: 26 | D22: =B22/C22 -> 0
A23: ZI usmeni | C23: 24 | D23: =B23/C23 -> 0 | E23: Ocjena: | F23: ECTS
A24: UKUPNO | B24: =SUM(B17:B23) -> 21 | C24: 100 | D24: =B24/C24 -> 0.21 | E24: =P9 -> 1 | F24: =IF($E$24 >1, 7, 0) -> 0
A26: MATAN#2 | B26: Moji Bodovi | C26: Maximum | D26: Postotak
A27: lil extra | C27: 5 | D27: =B27/C27 -> 0
A28: MI | C28: 50 | D28: =B28/C28 -> 0
A29: ZI | C29: 50 | D29: =B29/C29 -> 0 | E29: Ocjena: | F29: ECTS
A30: UKUPNO | B30: =SUM(B27:B29) -> 0 | C30: 100 | D30: =B30/C30 -> 0 | E30: =Q9 -> 1 | F30: =IF($E$30 >1, 7, 0) -> 0
A33: PITI | B33: Moji Bodovi | C33: Maximum | D33: Postotak
A34: ZI | B34: 28 | C34: 40 | D34: =B34/C34 -> 0.7 | E34: Ocjena: | F34: ECTS
A35: UKUPNO | B35: =B34 -> 28 | C35: 50 | D35: =B35/C35 -> 0.56 | E35: =R9 -> 3 | F35: =IF($E$35 >1, 2, 0) -> 2

Sheet SEM2_rokovi
A1: FIZIKA | B1: Moji Bodovi | C1: Maximum | D1: Postotak | F1: stanje :
A2: Labos | B2: ='SEM2'!B2 -> 8 | C2: 10 | D2: =B2/C2 -> 0.8 | F2: =SUM(F6:F23) -> 19 | L2: Racunanje ocjene | M2: FIZ | N2: OOP | O2: OE | P2: MATAN2 | Q2: PITI
A3: DZ | B3: ='SEM2'!B3 -> 0 | C3: 10 | D3: =B3/C3 -> 0 | L3: 1 | M3: 1 | N3: 1 | O3: 1 | P3: 1 | Q3: 1
A4: Pismeni | B4: 39 | C4: 56 | D4: =B4/C4 -> 0.69642857 | L4: 2 | M4: =IF($B$6 >= 50, 1, 0) -> 1 | N4: =IF($B$9 >= 50, 1, 0) -> 0 | O4: =IF($B$18 >= 50, 1, 0) -> 1 | P4: =IF($B$21 >= 50, 1,) -> 1 | Q4: =IF($B$24 >= 25.5, 1,) -> 0
A5: Usmeni | B5: 24 | C5: 24 | D5: =B5/C5 -> 1 | E5: Ocjena | F5: ECTS | L5: 3 | M5: =IF($B$6 >= 60, 1, 0) -> 1 | N5: =IF($B$9 >= 65, 1, 0) -> 0 | O5: =IF($B$18 >= 62, 1, ) -> 1 | P5: =IF($B$21 >= 58, 1, ) -> 0 | Q5: =IF($B$24 >= 30.5, 1,) -> 0
A6: Ukupno | B6: =SUM(B2:B5) -> 71 | C6: 100 | D6: =B6/C6 -> 0.71 | E6: =M8 -> 4 | F6: =IF($E$6 >1, 6, 0) -> 6 | L6: 4 | M6: =IF($B$6 >= 70, 1, 0) -> 1 | N6: =IF($B$9 >= 80, 1, 0) -> 0 | O6: =IF($B$18 >= 74, 1, 0) -> 0 | P6: =IF($B$21 >= 72, 1, ) -> 0 | Q6: =IF($B$24 >= 38.5, 1,) -> 0
L7: 5 | M7: =IF($B$6 >= 85, 1, 0) -> 0 | N7: =IF($B$9 >= 90, 1, 0) -> 0 | O7: =IF($B$18 >= 86, 1, 0) -> 0 | P7: =IF($B$21 >= 86, 1, 0) -> 0 | Q7: =IF($B$24 >= 45.5, 1,) -> 0
A8: OOP | B8: Moji Bodovi | C8: Maximum | D8: Postotak | E8: Ocjena | F8: ECTS | L8: zbroj | M8: =SUM(M3:M7) -> 4 | N8: =SUM(N3:N7) -> 1 | O8: =SUM(O3:O7) -> 3 | P8: =SUM(P3:P7) -> 2 | Q8: =SUM(Q3:Q7) -> 1
A9: Ispit | C9: 100 | D9: =B9/C9 -> 0 | E9: =N8 -> 1 | F9: =IF($E$9 >1, 8, 0) -> 0
A11: OE | B11: Moji Bodovi | C11: Maximum | D11: Postotak
A12: Labos | B12: ='SEM2'!B17 -> 6 | C12: 6 | D12: =B12/C12 -> 1
A13: DZ | B13: ='SEM2'!B18 -> 5 | C13: 5 | D13: =B13/C13 -> 1
A14: KPZ | B14: ='SEM2'!B19 -> 7 | C14: 9 | D14: =B14/C14 -> 0.77777778
A15: lil extra | B15: ='SEM2'!B20 -> 3 | C15: 4 | D15: =B15/C15 -> 0.75
A16: Pismeni | B16: 36 | C16: 52 | D16: =B16/C16 -> 0.69230769
A17: Usmeni | B17: =C17*(B16/C16) -> 16.615385 | C17: 24 | D17: =B17/C17 -> 0.69230769 | E17: Ocjena | F17: ECTS
A18: Ukupno | B18: =SUM(B12:B17) -> 73.615385 | C18: 100 | D18: =B18/C18 -> 0.73615385 | E18: =O8 -> 3 | F18: =IF($E$18 >1, 7, 0) -> 7
A20: Matan2 | B20: Moji Bodovi | C20: Maximum | D20: Postotak | E20: Ocjena | F20: ECTS
A21: Ispit | B21: 51 | C21: 100 | D21: =B21/C21 -> 0.51 | E21: =P8 -> 2 | F21: =IF($E$21 >1, 6, 0) -> 6
A23: PITI | B23: Moji Bodovi | C23: Maximum | D23: Postotak | E23: Ocjena | F23: ECTS
A24: Ispit | C24: 100 | D24: =B24/C24 -> 0 | E24: =Q8 -> 1 | F24: =IF($E$24 >1, 37, 0) -> 0

Sheet SEM3_E
A1: Elektronika | B1: Moji bodovi | C1: Max | D1: Postotak | F1: stanje : | I1: Racunanje ocjene | J1: ele1 | K1: elekru | L1: fiz2 | M1: MATAN2 | N1: mue | O1: inzeko | P1: LINALG
A2: Labosi | C2: 12 | D2: =B2/C2 -> 0 | F2: =SUM(F5:F45) -> 0 | I2: 1 | J2: 1 | K2: 1 | L2: 1 | M2: 1 | N2: 1 | O2: 1 | P2: 1
A3: MI | C3: 44 | D3: =B3/C3 -> 0 | I3: 2 | J3: =IF($B5 >= 50, 1, 0) -> 0 | K3: =IF($B$14 >= 50, 1, 0) -> 0 | L3: =IF($B$22 >= 50, 1, 0) -> 0 | M3: =IF($B$29 >= 45, 1,) -> 0 | N3: =IF($B$37 >= 50, 1,) -> 0 | O3: =IF($B$45 >= 50, 1,) -> 0 | P3: =IF($B$52 >= 45, 1, 0) -> 0
A4: ZI | C4: 44 | D4: =B4/C4 -> 0 | E4: Ocjena | F4: ECTS | I4: 3 | J4: =IF($B$5 >= 62, 1, 0) -> 0 | K4: =IF($B$14 >= 62, 1, 0) -> 0 | L4: =IF($B$22 >= 60, 1, ) -> 0 | M4: =IF($B$29 >= 55, 1, ) -> 0 | N4: =IF($B$37 >= 63, 1,) -> 0 | O4: =IF($B$45 >= 60, 1,) -> 0 | P4: =IF($B$52 >= 55, 1, ) -> 0
A5: UKUPNO | B5: =SUM(B2:B4) -> 0 | C5: 100 | D5: =B5/C5 -> 0 | E5: =J7 -> 1 | F5: =IF($E$5 >1, 6, 0) -> 0 | I5: 4 | J5: =IF($B$5 >= 75, 1, 0) -> 0 | K5: =IF($B$14 >= 75, 1, 0) -> 0 | L5: =IF($B$22 >= 70, 1, 0) -> 0 | M5: =IF($B$29 >= 70, 1, ) -> 0 | N5: =IF($B$37 >= 76, 1,) -> 0 | O5: =IF($B$45 >= 72, 1,) -> 0 | P5: =IF($B$52 >= 70, 1, 0) -> 0
I6: 5 | J6: =IF($B$5 >= 87, 1, 0) -> 0 | K6: =IF($B$14 >= 90, 1, 0) -> 0 | L6: =IF($B$22 >= 85, 1, 0) -> 0 | M6: =IF($B$29 >= 85, 1, 0) -> 0 | N6: =IF($B$37 >= 89, 1,) -> 0 | O6: =IF($B$45 >= 85, 1,) -> 0 | P6: =IF($B$52 >= 85, 1, 0) -> 0
I7: zbroj | J7: =SUM(J2:J6) -> 1 | K7: =SUM(K2:K6) -> 1 | L7: =SUM(L2:L6) -> 1 | M7: =SUM(M2:M6) -> 1 | N7: =SUM(N2:N6) -> 1 | O7: =SUM(O2:O6) -> 1 | P7: =SUM(P2:P6) -> 1
A8: EleKru | B8: Moji bodovi | C8: Max | D8: Postotak
A9: Labosi | C9: 15 | D9: =B9/C9 -> 0
A10: DZ | C10: 8 | D10: =B10/C10 -> 0
A11: prisutnost | C11: 2 | D11: =B11/C11 -> 0
A12: MI | C12: 35 | D12: =B12/C12 -> 0 | E12: =(B13+B12)/(C12+C13) -> 0
A13: ZI | C13: 40 | D13: =B13/C13 -> 0 | E13: Ocjena | F13: ECTS
A14: UKUPNO | B14: =SUM(B9:B13) -> 0 | C14: =SUM(C9:C13) -> 100 | D14: =B14/C14 -> 0 | E14: =K7 -> 1 | F14: =IF($E$14 >1, 5, 0) -> 0
A17: FIZIKA | B17: Moji Bodovi | C17: Max | D17: Postotak
A18: Labos | C18: 10 | D18: =B18/C18 -> 0 | E18: 3x
A19: DZ | C19: 10 | D19: =B19/C19 -> 0
A20: MI | C20: 40 | D20: =B20/C20 -> 0
A21: ZI | C21: 40 | D21: =B21/C21 -> 0 | E21: Ocjena: | F21: ECTS
A22: UKUPNO | B22: =SUM(B18:B21) -> 0 | C22: 100 | D22: =B22/C22 -> 0 | E22: =L7 -> 1 | F22: =IF($E$22 >1, 6, 0) -> 0
A25: MATAN#3 | B25: Moji Bodovi | C25: Maximum | D25: Postotak
A26: DZ | C26: 5 | D26: =B26/C26 -> 0
A27: MI | C27: 50 | D27: =B27/C27 -> 0
A28: ZI | C28: 50 | D28: =B28/C28 -> 0 | E28: Ocjena: | F28: ECTS
A29: UKUPNO | B29: =SUM(B26:B28) -> 0 | C29: 100 | D29: =B29/C29 -> 0 | E29: =M7 -> 1 | F29: =IF($E$29 >1, 7, 0) -> 0
A32: MuEle | B32: Moji bodovi | C32: Max | D32: Postotak
A33: Labosi | C33: 20 | D33: =B33/C33 -> 0
A34: MI | C34: 10 | D34: =B34/C34 -> 0 | E34: =(B34+B35)/(C34+C35) -> 0
A35: ZI pismeni | C35: 30 | D35: =B35/C35 -> 0
A36: ZI usmeni | C36: 40 | D36: =B36/C36 -> 0 | E36: Ocjena | F36: ECTS
A37: UKUPNO | B37: =SUM(B32:B36) -> 0 | C37: =SUM(C33:C36) -> 100 | D37: =B37/C37 -> 0 | E37: =N7 -> 1 | F37: =IF($E$37 >1, 4, 0) -> 0
A40: Inžeko | B40: Moji bodovi | C40: Max | D40: Postotak
A41: DZ | C41: 20 | D41: =B41/C41 -> 0
A42: Sudjelovanje | C42: 10 | D42: =B42/C42 -> 0
A43: MI | C43: 30 | D43: =B43/C43 -> 0
A44: ZI | C44: 40 | D44: =B44/C44 -> 0 | E44: Ocjena | F44: ECTS
A45: UKUPNO | B45: =SUM(B41:B44) -> 0 | C45: =SUM(C41:C44) -> 100 | D45: =B45/C45 -> 0 | E45: =O7 -> 1 | F45: =IF($E$45 >1, 2, 0) -> 0
A48: LINALG | B48: Moji Bodovi | C48: Maximum | D48: Postotak
A49: Zadaće | C49: 5 | D49: =B49/C49 -> 0
A50: MI | C50: 50 | D50: =B50/C50 -> 0
...

Sheet SEM3_R
A1: ViS | B1: Moji bodovi | C1: Max | D1: Postotak | F1: stanje : | J1: Racunanje ocjena | K1: VIS | L1: ASP | M1: ARH | N1: DISMAT | O1: TINF | P1: inzeko
A2: kpz | C2: 10 | D2: =B2/C2 -> 0 | F2: =SUM(F5:F43) -> 0 | J2: 1 | K2: 1 | L2: 1 | M2: 1 | N2: 1 | O2: 1 | P2: 1
A3: MI | C3: 50 | D3: =B3/C3 -> 0 | J3: 2 | K3: =IF($B5 >= 45, 1, 0) -> 0 | L3: =IF($B$12 >= 50, 1, 0) -> 0 | M3: =IF($B$19 >= 50, 1, 0) -> 0 | N3: =IF($B$27 >= 45, 1,) -> 0 | O3: =IF($B$33 >= 40, 1,) -> 0 | P3: =IF($B$41 >= 50, 1,) -> 0
A4: ZI | C4: 40 | D4: =B4/C4 -> 0 | E4: Ocjena | F4: ECTS | J4: 3 | K4: =IF($B$5 >= 55, 1, 0) -> 0 | L4: =IF($B$12 >= 62.5, 1, 0) -> 0 | M4: =IF($B$19 >= 65, 1, 0) -> 0 | N4: =IF($B$27 >= 50, 1,) -> 0 | O4: =IF($B$33 >= 55, 1,) -> 0 | P4: =IF($B$41 >= 60, 1,) -> 0
A5: UKUPNO: | B5: =SUM(B2:B4) -> 0 | C5: =SUM(C2:C4) -> 100 | D5: =B5/C5 -> 0 | E5: =K7 -> 1 | F5: =IF($E$5 >1, 6, 0) -> 0 | J5: 4 | K5: =IF($B$5 >= 70, 1, 0) -> 0 | L5: =IF($B$12 >= 75, 1, 0) -> 0 | M5: =IF($B$19 >= 80, 1, 0) -> 0 | N5: =IF($B$27 >= 70, 1,) -> 0 | O5: =IF($B$33 >= 70, 1,) -> 0 | P5: =IF($B$41 >= 72, 1,) -> 0
J6: 5 | K6: =IF($B$5 >= 85, 1, 0) -> 0 | L6: =IF($B$12 >= 87.5, 1, 0) -> 0 | M6: =IF($B$19 >= 90, 1, 0) -> 0 | N6: =IF($B$27 >= 85, 1,) -> 0 | O6: =IF($B$33 >= 85, 1,) -> 0 | P6: =IF($B$41 >= 85, 1,) -> 0
J7: zbroj | K7: =SUM(K2:K6) -> 1 | L7: =SUM(L2:L6) -> 1 | M7: =SUM(M2:M6) -> 1 | N7: =SUM(N2:N6) -> 1 | O7: =SUM(O2:O6) -> 1 | P7: =SUM(P2:P6) -> 1
A8: ASP | B8: Moji bodovi | C8: Max | D8: Postotak
A9: Labosi | C9: 15 | D9: =B9/C9 -> 0
A10: MI | C10: 40 | D10: =B10/C10 -> 0
A11: ZI | C11: 45 | D11: =B11/C11 -> 0 | E11: Ocjena | F11: ECTS
A12: Ukupno | B12: =SUM(B9:B11) -> 0 | C12: =SUM(C9:C11) -> 100 | D12: =B12/C12 -> 0 | E12: =L7 -> 1 | F12: =IF($E$12 >1, 6, 0) -> 0
A15: ARH | B15: Moji bodovi | C15: Max | D15: Postotak
A16: Labosi | C16: 15 | D16: =B16/C16 -> 0
A17: MI | C17: 40 | D17: =B17/C17 -> 0
A18: ZI | C18: 45 | D18: =B18/C18 -> 0 | E18: Ocjena | F18: ECTS
A19: UKUPNO | B19: =SUM(B16:B18) -> 0 | C19: =SUM(C16:C18) -> 100 | D19: =B19/C19 -> 0 | E19: =M7 -> 1 | F19: =IF($E$19 >1, 6, 0) -> 0
A22: DisMat | B22: Moji bodovi | C22: Max | D22: Postotak
A23: Labosi | C23: 15 | D23: =B23/C23 -> 0
A24: DZ | C24: 5 | D24: =B24/C24 -> 0
A25: MI | C25: 40 | D25: =B25/C25 -> 0
A26: ZI | C26: 40 | D26: =B26/C26 -> 0 | E26: Ocjena | F26: ECTS
A27: UKUPNO | B27: =SUM(B23:B26) -> 0 | C27: 100 | D27: =B27/C27 -> 0 | E27: =N7 -> 1 | F27: =IF($E$27 >1, 6, 0) -> 0
A30: TINF | B30: Moji bodovi | C30: Max | D30: Postotak
A31: MI | C31: 50 | D31: =B31/C31 -> 0
A32: ZI | C32: 50 | D32: =B32/C32 -> 0 | E32: Ocjena | F32: ECTS
A33: UKUPNO | B33: =SUM(B31:B32) -> 0 | C33: =SUM(C31:C32) -> 100 | D33: =B33/C33 -> 0 | E33: =O7 -> 1 | F33: =IF($E$33 >1, 4, 0) -> 0
A36: Inžeko | B36: Moji bodovi | C36: Max | D36: Postotak
A37: DZ | C37: 20 | D37: =B37/C37 -> 0
A38: Sudjelovanje | C38: 10 | D38: =B38/C38 -> 0
A39: MI | C39: 30 | D39: =B39/C39 -> 0
A40: ZI | C40: 40 | D40: =B40/C40 -> 0 | E40: Ocjena | F40: ECTS
A41: UKUPNO | B41: =SUM(B37:B40) -> 0 | C41: =SUM(C37:C40) -> 100 | D41: =B41/C41 -> 0 | E41: =P7 -> 1 | F41: =IF($E$41 >1, 2, 0) -> 0

Sheet SEM3_rokovi
A1: Elektronika | B1: Moji bodovi | C1: Max | D1: Postotak | F1: stanje : | I1: ViS | J1: Moji bodovi | K1: Max | L1: Postotak | N1: stanje : | S1: Racunanje ocjene | T1: ele1 | U1: elekru | V1: fiz2 | W1: MATAN2 | X1: mue | Y1: inzeko
A2: Labosi | B2: =SEM3_E!B2 -> 0 | C2: 12 | D2: =B2/C2 -> 0 | F2: =SUM(F5:F40) -> 0 | I2: kpz | J2: =SEM3_R!B2 -> 0 | K2: 10 | L2: =J2/K2 -> 0 | N2: =SUM(N4:N42) -> 0 | S2: 1 | T2: 1 | U2: 1 | V2: 1 | W2: 1 | X2: 1 | Y2: 1
A3: Pismeni | C3: 50 | D3: =B3/C3 -> 0 | I3: Pismeni | K3: 40 | L3: =J3/K3 -> 0 | M3: Ocjena | N3: ECTS | S3: 2 | T3: =IF($B5 >= 50, 1, 0) -> 0 | U3: =IF($B$14 >= 50, 1, 0) -> 0 | V3: =IF($B$22 >= 50, 1, 0) -> 0 | W3: =IF($B$29 >= 45, 1,) -> 0 | X3: =IF($B$37 >= 50, 1,) -> 0 | Y3: =IF($B$45 >= 50, 1,) -> 0
A4: Usmeni | C4: 38 | D4: =B4/C4 -> 0 | E4: Ocjena | F4: ECTS | I4: UKUPNO: | J4: =SUM(J2:J3) -> 0 | K4: =SUM(K2:K3) -> 50 | L4: =J4/K4 -> 0 | M4: =T7 -> 1 | N4: =IF($M$4 >1, 6, 0) -> 0 | S4: 3 | T4: =IF($B$5 >= 62, 1, 0) -> 0 | U4: =IF($B$14 >= 62, 1, 0) -> 0 | V4: =IF($B$22 >= 60, 1, ) -> 0 | W4: =IF($B$29 >= 55, 1, ) -> 0 | X4: =IF($B$37 >= 63, 1,) -> 0 | Y4: =IF($B$45 >= 60, 1,) -> 0
A5: UKUPNO | B5: =SUM(B2:B4) -> 0 | C5: 100 | D5: =B5/C5 -> 0 | E5: =T7 -> 1 | F5: =IF($E$5 >1, 6, 0) -> 0 | S5: 4 | T5: =IF($B$5 >= 75, 1, 0) -> 0 | U5: =IF($B$14 >= 75, 1, 0) -> 0 | V5: =IF($B$22 >= 70, 1, 0) -> 0 | W5: =IF($B$29 >= 70, 1, ) -> 0 | X5: =IF($B$37 >= 76, 1,) -> 0 | Y5: =IF($B$45 >= 72, 1,) -> 0
S6: 5 | T6: =IF($B$5 >= 87, 1, 0) -> 0 | U6: =IF($B$14 >= 90, 1, 0) -> 0 | V6: =IF($B$22 >= 85, 1, 0) -> 0 | W6: =IF($B$29 >= 85, 1, 0) -> 0 | X6: =IF($B$37 >= 89, 1,) -> 0 | Y6: =IF($B$45 >= 85, 1,) -> 0
I7: ASP | J7: Moji bodovi | K7: Max | L7: Postotak | S7: zbroj | T7: =SUM(T2:T6) -> 1 | U7: =SUM(U2:U6) -> 1 | V7: =SUM(V2:V6) -> 1 | W7: =SUM(W2:W6) -> 1 | X7: =SUM(X2:X6) -> 1 | Y7: =SUM(Y2:Y6) -> 1
A8: EleKru | B8: Moji bodovi | C8: Max | D8: Postotak | I8: Labosi | J8: =SEM3_R!B9 -> 0 | K8: 15 | L8: =J8/K8 -> 0
A9: Labosi | B9: =SEM3_E!B9 -> 0 | C9: 15 | D9: =B9/C9 -> 0 | I9: MI | K9: 40 | L9: =J9/K9 -> 0
A10: DZ | B10: =SEM3_E!B10 -> 0 | C10: 8 | D10: =B10/C10 -> 0 | I10: ZI | K10: 45 | L10: =J10/K10 -> 0 | M10: Ocjena | N10: ECTS
A11: prisutnost | B11: =SEM3_E!B11 -> 0 | C11: 2 | D11: =B11/C11 -> 0 | I11: Ukupno | J11: =SUM(J8:J10) -> 0 | K11: =SUM(K8:K10) -> 100 | L11: =J11/K11 -> 0 | M11: =T7 -> 1 | N11: =IF(M11 >1, 6, 0) -> 0 | S11: Racunanje ocjena | T11: VIS | U11: ASP | V11: ARH | W11: DISMAT | X11: TINF | Y11: inzeko
A12: Pismeni | C12: 40 | D12: =B12/C12 -> 0 | E12: Ocjena | F12: ECTS | S12: 1 | T12: 1 | U12: 1 | V12: 1 | W12: 1 | X12: 1 | Y12: 1
A13: UKUPNO | B13: =SUM(B9:B12) -> 0 | C13: =SUM(C9:C12) -> 65 | D13: =B13/C13 -> 0 | E13: =U7 -> 1 | F13: =IF($E$13 >1, 5, 0) -> 0 | S13: 2 | T13: =IF($J4 >= 45, 1, 0) -> 0 | U13: =IF($J$11 >= 50, 1, 0) -> 0 | V13: =IF($J$17 >= 50, 1, 0) -> 0 | W13: =IF($J$24 >= 45, 1,) -> 0 | X13: =IF($J$29 >= 40, 1,) -> 0 | Y13: =IF($J$37 >= 50, 1,) -> 0
I14: ARH | J14: Moji bodovi | K14: Max | L14: Postotak | S14: 3 | T14: =IF($J$4 >= 55, 1, 0) -> 0 | U14: =IF($J$11 >= 62.5, 1, 0) -> 0 | V14: =IF($J$17 >= 65, 1, 0) -> 0 | W14: =IF($J$24 >= 50, 1,) -> 0 | X14: =IF($J$29 >= 55, 1,) -> 0 | Y14: =IF($J$37 >= 60, 1,) -> 0
I15: Labosi | J15: =SEM3_R!B16 -> 0 | K15: 15 | L15: =J15/K15 -> 0 | S15: 4 | T15: =IF($J$4 >= 70, 1, 0) -> 0 | U15: =IF($J$11 >= 75, 1, 0) -> 0 | V15: =IF($B$5 >= 80, 1, 0) -> 0 | W15: =IF($J$24 >= 70, 1,) -> 0 | X15: =IF($J$29 >= 70, 1,) -> 0 | Y15: =IF($J$37 >= 72, 1,) -> 0
A16: FIZIKA | B16: Moji Bodovi | C16: Max | D16: Postotak | I16: Pismeni | K16: 45 | L16: =J16/K16 -> 0 | M16: Ocjena | N16: ECTS | S16: 5 | T16: =IF($J$4 >= 85, 1, 0) -> 0 | U16: =IF($J$11 >= 87.5, 1, 0) -> 0 | V16: =IF($J$17 >= 90, 1, 0) -> 0 | W16: =IF($J$24 >= 85, 1,) -> 0 | X16: =IF($J$29 >= 85, 1,) -> 0 | Y16: =IF($J$37 >= 85, 1,) -> 0
A17: Labos | B17: =SEM3_E!B18 -> 0 | C17: 10 | D17: =B17/C17 -> 0 | E17: 3x | I17: UKUPNO | J17: =SUM(J15:J16) -> 0 | K17: =SUM(K15:K16) -> 60 | L17: =J17/K17 -> 0 | M17: =U7 -> 1 | N17: =IF($E$18 >1, 6, 0) -> 0 | S17: zbroj | T17: =SUM(T12:T16) -> 1 | U17: =SUM(U12:U16) -> 1 | V17: =SUM(V12:V16) -> 1 | W17: =SUM(W12:W16) -> 1 | X17: =SUM(X12:X16) -> 1 | Y17: =SUM(Y12:Y16) -> 1
A18: DZ | B18: =SEM3_E!B19 -> 0 | C18: 10 | D18: =B18/C18 -> 0
A19: Pismeni | C19: 40 | D19: =B19/C19 -> 0 | E19: Ocjena: | F19: ECTS
A20: UKUPNO | B20: =SUM(B17:B19) -> 0 | C20: 100 | D20: =B20/C20 -> 0 | E20: =V7 -> 1 | F20: =IF($E$20 >1, 6, 0) -> 0 | I20: DisMat | J20: Moji bodovi | K20: Max | L20: Postotak
I21: Labosi | J21: =SEM3_R!B23 -> 0 | K21: 15 | L21: =J21/K21 -> 0
I22: DZ | J22: =SEM3_R!B24 -> 0 | K22: 5 | L22: =J22/K22 -> 0
A23: MATAN#3 | B23: Moji Bodovi | C23: Maximum | D23: Postotak | I23: Pismeni | K23: 40 | L23: =J23/K23 -> 0 | M23: Ocjena | N23: ECTS
A24: Pismeni | C24: 100 | D24: =B24/C24 -> 0 | E24: Ocjena: | F24: ECTS | I24: UKUPNO | J24: =SUM(J21:J23) -> 0 | K24: 100 | L24: =J24/K24 -> 0 | M24: =V7 -> 1 | N24: =IF(M24 >1, 6, 0) -> 0
A25: UKUPNO | B25: =B24 -> 0 | C25: 100 | D25: =B25/C25 -> 0 | E25: =W7 -> 1 | F25: =IF($E$25 >1, 7, 0) -> 0
I27: TINF | J27: Moji bodovi | K27: Max | L27: Postotak
A28: MuEle | B28: Moji bodovi | C28: Max | D28: Postotak | I28: Pismeni | K28: 50 | L28: =J28/K28 -> 0 | M28: Ocjena | N28: ECTS
A29: Labosi | B29: =SEM3_E!B33 -> 0 | C29: 20 | D29: =B29/C29 -> 0 | I29: UKUPNO | J29: =SUM(J28:J28) -> 0 | K29: =SUM(K28:K28) -> 50 | L29: =J29/K29 -> 0 | M29: =W7 -> 1 | N29: =IF($E$29 >1, 4, 0) -> 0
A30: Pismeni | C30: 40 | D30: =B30/C30 -> 0
A31: Usmeni | C31: 40 | D31: =B31/C31 -> 0 | E31: Ocjena | F31: ECTS
A32: UKUPNO | B32: =SUM(B28:B31) -> 0 | C32: =SUM(C29:C31) -> 100 | D32: =B32/C32 -> 0 | E32: =X7 -> 1 | F32: =IF($E$32 >1, 4, 0) -> 0 | I32: Inžeko | J32: Moji bodovi | K32: Max | L32: Postotak
I33: DZ | J33: =SEM3_R!B37 -> 0 | K33: 20 | L33: =J33/K33 -> 0
I34: Sudjelovanje | J34: =SEM3_R!B38 -> 0 | K34: 10 | L34: =J34/K34 -> 0
A35: Inžeko | B35: Moji bodovi | C35: Max | D35: Postotak | I35: Pismeni | K35: 30 | L35: =J35/K35 -> 0
A36: DZ | B36: =SEM3_E!B41 -> 0 | C36: 20 | D36: =B36/C36 -> 0 | I36: Usmeni | K36: 40 | L36: =J36/K36 -> 0 | M36: Ocjena | N36: ECTS
A37: Sudjelovanje | B37: =SEM3_E!B42 -> 0 | C37: 10 | D37: =B37/C37 -> 0 | I37: UKUPNO | J37: =SUM(J33:J36) -> 0 | K37: =SUM(K33:K36) -> 100 | L37: =J37/K37 -> 0 | M37: =X7 -> 1 | N37: =IF($E$36 >1, 2, 0) -> 0
A38: Pismeni | C38: 30 | D38: =B38/C38 -> 0
A39: Usmeni | C39: 40 | D39: =B39/C39 -> 0 | E39: Ocjena | F39: ECTS
A40: UKUPNO | B40: =SUM(B36:B39) -> 0 | C40: =SUM(C36:C39) -> 100 | D40: =B40/C40 -> 0 | E40: =Y7 -> 1 | F40: =IF($E$40 >1, 2, 0) -> 0

Sheet SEM4_E
A1: ELE2 | B1: Moji bodovi | C1: Max | D1: Postotak | F1: stanje : | I1: Racunanje ocjene | J1: ele2 | K1: sis | L1: arh1e | M1: vis | N1: eleen | O1: mnijenje
A2: Labosi | C2: 12 | D2: =B2/C2 -> 0 | F2: =SUM(F6:F44) -> 0 | I2: 1 | J2: 1 | K2: 1 | L2: 1 | M2: 1 | N2: 1 | O2: 1
A3: MI | C3: 30 | D3: =B3/C3 -> 0 | I3: 2 | J3: =IF($B6 >= 50, 1, 0) -> 0 | K3: =IF($B$14 >= 51, 1, 0) -> 0 | L3: =IF($B$22 >= 50, 1, 0) -> 0 | M3: =IF($B$29 >= 45, 1,) -> 0 | N3: =IF($B$36 >= 50, 1,) -> 0 | O3: =IF($B$44 >= 50, 1,) -> 0
A4: ZI: pismeni | C4: 30 | D4: =B4/C4 -> 0 | I4: 3 | J4: =IF($B$6 >= 62, 1, 0) -> 0 | K4: =IF($B$14 >= 63, 1, 0) -> 0 | L4: =IF($B$22 >= 65, 1, ) -> 0 | M4: =IF($B$29 >= 55, 1, ) -> 0 | N4: =IF($B$36 >= 60, 1,) -> 0 | O4: =IF($B$44 >= 60, 1,) -> 0
A5: ZI: usmeni | C5: 28 | D5: =B5/C5 -> 0 | E5: Ocjena | F5: ECTS | I5: 4 | J5: =IF($B$6 >= 75, 1, 0) -> 0 | K5: =IF($B$14 >= 75, 1, 0) -> 0 | L5: =IF($B$22 >= 80, 1, 0) -> 0 | M5: =IF($B$29 >= 70, 1, ) -> 0 | N5: =IF($B$36 >= 75, 1,) -> 0 | O5: =IF($B$44 >= 75, 1,) -> 0
A6: UKUPNO | B6: =SUM(B2:B5) -> 0 | C6: 100 | D6: =B6/C6 -> 0 | E6: =J7 -> 1 | F6: =IF($E$6 >1, 6, 0) -> 0 | I6: 5 | J6: =IF($B$6 >= 87, 1, 0) -> 0 | K6: =IF($B$14 >= 87, 1, 0) -> 0 | L6: =IF($B$22 >= 90, 1, 0) -> 0 | M6: =IF($B$29 >= 85, 1, 0) -> 0 | N6: =IF($B$36 >= 90, 1,) -> 0 | O6: =IF($B$44 >= 85, 1,) -> 0
I7: zbroj | J7: =SUM(J2:J6) -> 1 | K7: =SUM(K2:K6) -> 1 | L7: =SUM(L2:L6) -> 1 | M7: =SUM(M2:M6) -> 1 | N7: =SUM(N2:N6) -> 1 | O7: =SUM(O2:O6) -> 1
A8: SIS | B8: Moji bodovi | C8: Max | D8: Postotak
A9: Labosi | C9: 6 | D9: =B9/C9 -> 0
A10: DZ | C10: 10 | D10: =B10/C10 -> 0
A11: sudjelovanje | C11: 4 | D11: =B11/C11 -> 0
A12: MI | C12: 40 | D12: =B12/C12 -> 0
A13: ZI | C13: 40 | D13: =B13/C13 -> 0 | E13: Ocjena | F13: ECTS
A14: UKUPNO | B14: =SUM(B9:B13) -> 0 | C14: =SUM(C9:C13) -> 100 | D14: =B14/C14 -> 0 | E14: =K7 -> 1 | F14: =IF($E$14 >1, 5, 0) -> 0
A17: ARH1_E | B17: Moji Bodovi | C17: Max | D17: Postotak
A18: Labos | C18: 15 | D18: =B18/C18 -> 0 | E18: 3x
A19: kpz | C19: 15 | D19: =B19/C19 -> 0
A20: MI | C20: 30 | D20: =B20/C20 -> 0
A21: ZI | C21: 40 | D21: =B21/C21 -> 0 | E21: Ocjena: | F21: ECTS
A22: UKUPNO | B22: =SUM(B18:B21) -> 0 | C22: 100 | D22: =B22/C22 -> 0 | E22: =L7 -> 1 | F22: =IF($E$22 >1, 4, 0) -> 0
A25: VIS_E | B25: Moji Bodovi | C25: Max | D25: Postotak
A26: kpz | C26: 10 | D26: =B26/C26 -> 0
A27: MI | C27: 50 | D27: =B27/C27 -> 0
A28: ZI | C28: 40 | D28: =B28/C28 -> 0 | E28: Ocjena: | F28: ECTS
A29: UKUPNO | C29: 100 | D29: =B29/C29 -> 0 | E29: =M7 -> 1 | F29: =IF($E$29 >1, 7, 0) -> 0
A32: ELEEN | B32: Moji bodovi | C32: Max | D32: Postotak
A33: kpz | C33: 6 | D33: =B33/C33 -> 0
A34: MI | C34: 38 | D34: =B34/C34 -> 0
A35: ZI | C35: 56 | D35: =B35/C35 -> 0 | E35: Ocjena | F35: ECTS
A36: UKUPNO | B36: =SUM(B32:B35) -> 0 | C36: =SUM(C33:C35) -> 100 | D36: =B36/C36 -> 0 | E36: =N7 -> 1 | F36: =IF($E$36 >1, 6, 0) -> 0
A40: Mnijenje | B40: Moji bodovi | C40: Max | D40: Postotak
A41: Sudjelovanje | C41: 30 | D41: =B41/C41 -> 0
A42: MI | C42: 35 | D42: =B42/C42 -> 0
A43: ZI | C43: 35 | D43: =B43/C43 -> 0 | E43: Ocjena | F43: ECTS
A44: UKUPNO | B44: =SUM(B41:B43) -> 0 | C44: =SUM(C41:C43) -> 100 | D44: =B44/C44 -> 0 | E44: =O7 -> 1 | F44: =IF($E$44 >1, 2, 0) -> 0

Sheet SEM4_R
A1: BazP | B1: Moji bodovi | C1: Max | D1: Postotak | F1: stanje : | J1: Racunanje ocjena | K1: BazP | L1: KoMre | M1: OpS | N1: RPPW | O1: UTR | P1: mnijenje
A2: Labosi | C2: 32 | D2: =B2/C2 -> 0 | F2: =SUM(F6:F45) -> #REF! | J2: 1 | K2: 1 | L2: 1 | M2: 1 | N2: 1 | O2: 1 | P2: 1
A3: ZI | C3: 8 | D3: =B3/C3 -> 0 | J3: 2 | K3: =IF($B6 >= 50, 1, 0) -> 0 | L3: =IF($B$14 >= 50, 1, 0) -> 0 | M3: =IF($B$22 >= 50, 1, 0) -> 0 | N3: =IF($B$29 >= 50, 1,) -> 0 | O3: =IF($B$38 >= 50, 1,) -> 0 | P3: =IF($B$45 >= 50, 1,) -> 0
A4: MI | C4: 30 | D4: =B4/C4 -> 0 | J4: 3 | K4: =IF($B$6 >= 62.5, 1, 0) -> 0 | L4: =IF($B$14 >= 60, 1, 0) -> 0 | M4: =IF($B$22 >= 63, 1, 0) -> 0 | N4: =IF($B$29 >= 62.5, 1,) -> 0 | O4: =IF($B$38 >= 63, 1,) -> 0 | P4: =IF($B$45 >= 60, 1,) -> 0
A5: ZI | C5: 30 | D5: =B5/C5 -> 0 | E5: Ocjena | F5: ECTS | J5: 4 | K5: =IF($B$6 >= 75, 1, 0) -> 0 | L5: =IF($B$14 >= 70, 1, 0) -> 0 | M5: =IF($B$22 >= 75, 1, 0) -> 0 | N5: =IF($B$29 >= 75, 1,) -> 0 | O5: =IF($B$38 >= 75, 1,) -> 0 | P5: =IF($B$45 >= 75, 1,) -> 0
A6: UKUPNO: | B6: =SUM(B2:B5) -> 0 | C6: =SUM(C2:C5) -> 100 | D6: =B6/C6 -> 0 | E6: =K7 -> 1 | F6: =IF($E$6 >1, 6, 0) -> 0 | J6: 5 | K6: =IF($B$6 >= 87.5, 1, 0) -> 0 | L6: =IF($B$14 >= 85, 1, 0) -> 0 | M6: =IF($B$22 >= 88, 1, 0) -> 0 | N6: =IF($B$29 >= 87.5, 1,) -> 0 | O6: =IF($B$38 >= 88, 1,) -> 0 | P6: =IF($B$45 >= 85, 1,) -> 0
J7: zbroj | K7: =SUM(K2:K6) -> 1 | L7: =SUM(L2:L6) -> 1 | M7: =SUM(M2:M6) -> 1 | N7: =SUM(N2:N6) -> 1 | O7: =SUM(O2:O6) -> 1 | P7: =SUM(P2:P6) -> 1
A8: KoMre | B8: Moji bodovi | C8: Max | D8: Postotak
A9: DZ
A10: Labosi
A11: kpz | C11: 10 | D11: =B11/C11 -> 0
A12: MI | C12: 35 | D12: =B12/C12 -> 0
A13: ZI | C13: 55 | D13: =B13/C13 -> 0 | E13: Ocjena | F13: ECTS
A14: Ukupno | B14: =SUM(B9:B13) -> 0 | C14: =SUM(C9:C13) -> 100 | D14: =B14/C14 -> 0 | E14: =L7 -> 1 | F14: =IF($E$14 >1, 6, 0) -> 0
A17: OS | B17: Moji bodovi | C17: Max | D17: Postotak
A18: kpz | C18: 10 | D18: =B18/C18 -> 0
A19: Labosi | C19: 20 | D19: =B19/C19 -> 0 | E19: x3
A20: MI | C20: 30 | D20: =B20/C20 -> 0
A21: ZI | C21: 40 | D21: =B21/C21 -> 0 | E21: Ocjena | F21: ECTS
A22: UKUPNO | B22: =SUM(B19:B21) -> 0 | C22: =SUM(C18:C21) -> 100 | D22: =B22/C22 -> 0 | E22: =M7 -> 1 | F22: =IF($E$22 >1, 6, 0) -> 0
A25: RPPW | B25: Moji bodovi | C25: Max | D25: Postotak
A26: Labosi | C26: 30 | D26: =B26/C26 -> 0
A27: MI | C27: 40 | D27: =B27/C27 -> 0
A28: ZI | C28: 40 | D28: =B28/C28 -> 0 | E28: Ocjena | F28: ECTS
A29: UKUPNO | B29: =SUM(B26:B28) -> 0 | C29: 100 | D29: =B29/C29 -> 0 | E29: =N7 -> 1 | F29: =IF($E$29 >1, 6, 0) -> 0
A33: UTR | B33: Moji bodovi | C33: Max | D33: Postotak
A34: Labosi | C34: 30 | D34: =B34/C34 -> 0
A35: sudjelovanje | C35: 10 | D35: =B35/C35 -> 0
A36: MI | C36: 30 | D36: =B36/C36 -> 0
A37: ZI | C37: 30 | D37: =B37/C37 -> 0 | E37: Ocjena | F37: ECTS
A38: UKUPNO | B38: =SUM(B36:B37) -> 0 | C38: =SUM(C34:C37) -> 100 | D38: =B38/C38 -> 0 | E38: =O7 -> 1 | F38: =IF($E$38 >1, 4, 0) -> 0
A41: Mnijenje | B41: Moji bodovi | C41: Max | D41: Postotak
A42: Sudjelovanje | C42: 30 | D42: =B42/C42 -> 0
A43: MI | C43: 35 | D43: =B43/C43 -> 0
A44: ZI | C44: 35 | D44: =B44/C44 -> 0 | E44: Ocjena | F44: ECTS
A45: UKUPNO | B45: =SUM(B42:B44) -> 0 | C45: =SUM(C42:C44) -> 100 | D45: =B45/C45 -> 0 | E45: =O3 -> 0 | F45: =IF(#REF! >1, 2, 0) -> #REF!

Sheet SEM4_rokovi
A1: ELE2 | B1: Moji bodovi | C1: Max | D1: Postotak | F1: stanje : | K1: BazP | L1: Moji bodovi | M1: Max | N1: Postotak | P1: stanje :
A2: Labosi | B2: =SEM4_E!B2 -> 0 | C2: 12 | D2: =B2/C2 -> 0 | F2: =SUM(F5:F36) -> 12 | K2: Labosi | M2: 32 | N2: =L2/M2 -> 0 | P2: =SUM(P6:P45) -> #REF!
A3: Pismeni | C3: 50 | D3: =B3/C3 -> 0 | K3: ZI | M3: 8 | N3: =L3/M3 -> 0
A4: Usmeni | C4: 28 | D4: =B4/C4 -> 0 | E4: Ocjena | F4: ECTS | K4: MI | M4: 30 | N4: =L4/M4 -> 0
A5: UKUPNO | B5: =SUM(B2:B4) -> 0 | C5: 100 | D5: =B5/C5 -> 0 | E5: =J6 -> 0 | F5: =IF($E$5 >1, 6, 0) -> 0 | K5: ZI | M5: 30 | N5: =L5/M5 -> 0 | O5: Ocjena | P5: ECTS
K6: UKUPNO: | L6: =SUM(L2:L5) -> 0 | M6: =SUM(M2:M5) -> 100 | N6: =L6/M6 -> 0 | O6: =U7 -> 0 | P6: =IF($E$6 >1, 6, 0) -> 0
A7: SIS | B7: Moji bodovi | C7: Max | D7: Postotak
A8: Labosi | B8: =SEM4_E!B9 -> 0 | C8: 6 | D8: =B8/C8 -> 0 | K8: KoMre | L8: Moji bodovi | M8: Max | N8: Postotak
A9: Pismeni | C9: 100 | D9: =B9/C9 -> 0 | E9: Ocjena | F9: ECTS | K9: DZ
A10: UKUPNO | B10: =SUM(B8:B9) -> 0 | C10: 100 | D10: =B10/C10 -> 0 | E10: =K6 -> UKUPNO: | F10: =IF($E$10 >1, 5, 0) -> 5 | K10: Labosi
K11: kpz | M11: 10 | N11: =L11/M11 -> 0
K12: MI | M12: 35 | N12: =L12/M12 -> 0
A13: ARH1_E | B13: Moji Bodovi | C13: Max | D13: Postotak | K13: ZI | M13: 55 | N13: =L13/M13 -> 0 | O13: Ocjena | P13: ECTS
A14: Labos | B14: =(SEM4_E!B18)/2 -> 0 | C14: 7.5 | D14: =B14/C14 -> 0 | K14: Ukupno | L14: =SUM(L9:L13) -> 0 | M14: =SUM(M9:M13) -> 100 | N14: =L14/M14 -> 0 | O14: =V7 -> 0 | P14: =IF($E$14 >1, 6, 0) -> 0
A15: kpz | B15: =(SEM4_E!B19)/2 -> 0 | C15: 7.5 | D15: =B15/C15 -> 0
A16: Pismeni | C16: 85 | D16: =B16/C16 -> 0 | E16: Ocjena: | F16: ECTS
A17: UKUPNO | B17: =SUM(B14:B16) -> 0 | C17: 100 | D17: =B17/C17 -> 0 | E17: =L3 -> 0 | F17: =IF($E$21 >1, 4, 0) -> 0 | K17: OS | L17: Moji bodovi | M17: Max | N17: Postotak
K18: kpz | M18: 10 | N18: =L18/M18 -> 0
K19: Labosi | M19: 20 | N19: =L19/M19 -> 0 | O19: x3
A20: VIS_E | B20: Moji Bodovi | C20: Max | D20: Postotak | K20: MI | M20: 30 | N20: =L20/M20 -> 0
A21: kpz | B21: =SEM4_E!B26 -> 0 | C21: 10 | D21: =B21/C21 -> 0 | K21: ZI | M21: 40 | N21: =L21/M21 -> 0 | O21: Ocjena | P21: ECTS
A22: ZI | C22: 90 | D22: =B22/C22 -> 0 | E22: Ocjena: | F22: ECTS | K22: UKUPNO | L22: =SUM(L19:L21) -> 0 | M22: =SUM(M18:M21) -> 100 | N22: =L22/M22 -> 0 | O22: =W7 -> 0 | P22: =IF($E$22 >1, 6, 0) -> 6
A23: UKUPNO | B23: =SUM(B21:B22) -> 0 | C23: 100 | D23: =B23/C23 -> 0 | E23: =M6 -> 100 | F23: =IF($E$23 >1, 7, 0) -> 7
K25: RPPW | L25: Moji bodovi | M25: Max | N25: Postotak
A26: ELEEN | B26: Moji bodovi | C26: Max | D26: Postotak | K26: Labosi | M26: 30 | N26: =L26/M26 -> 0
A27: kpz | B27: =SEM4_E!B33 -> 0 | C27: 6 | D27: =B27/C27 -> 0 | K27: MI | M27: 40 | N27: =L27/M27 -> 0
A28: Pismeni | C28: 94 | D28: =B28/C28 -> 0 | E28: Ocjena | F28: ECTS | K28: ZI | M28: 40 | N28: =L28/M28 -> 0 | O28: Ocjena | P28: ECTS
A29: UKUPNO | B29: =SUM(B26:B28) -> 0 | C29: =SUM(C27:C28) -> 100 | D29: =B29/C29 -> 0 | E29: =N6 -> 0 | F29: =IF($E$29 >1, 6, 0) -> 0 | K29: UKUPNO | L29: =SUM(L26:L28) -> 0 | M29: 100 | N29: =L29/M29 -> 0 | O29: =X7 -> 0 | P29: =IF($E$29 >1, 6, 0) -> 0
A33: Mnijenje | B33: Moji bodovi | C33: Max | D33: Postotak | K33: UTR | L33: Moji bodovi | M33: Max | N33: Postotak
A34: Sudjelovanje | C34: 30 | D34: =B34/C34 -> 0 | K34: Labosi | M34: 30 | N34: =L34/M34 -> 0
A35: ZI | C35: 70 | D35: =B35/C35 -> 0 | E35: Ocjena | F35: ECTS | K35: sudjelovanje | M35: 10 | N35: =L35/M35 -> 0
A36: UKUPNO | B36: =SUM(B34:B35) -> 0 | C36: =SUM(C34:C35) -> 100 | D36: =B36/C36 -> 0 | E36: =O6 -> 0 | F36: =IF($E$36 >1, 2, 0) -> 0 | K36: MI | M36: 30 | N36: =L36/M36 -> 0
K37: ZI | M37: 30 | N37: =L37/M37 -> 0 | O37: Ocjena | P37: ECTS
K38: UKUPNO | L38: =SUM(L36:L37) -> 0 | M38: =SUM(M34:M37) -> 100 | N38: =L38/M38 -> 0 | O38: =Y7 -> 0 | P38: =IF($E$38 >1, 4, 0) -> 0
K41: Mnijenje | L41: Moji bodovi | M41: Max | N41: Postotak
A42: Racunanje ocjene | B42: ele2 | C42: sis | D42: arh1e | E42: vis | F42: eleen | G42: mnijenje | K42: Sudjelovanje | M42: 30 | N42: =L42/M42 -> 0
A43: 1 | B43: 1 | C43: 1 | D43: 1 | E43: 1 | F43: 1 | G43: 1 | K43: MI | M43: 35 | N43: =L43/M43 -> 0
A44: 2 | B44: =IF($B5 >= 50, 1, 0) -> 0 | C44: =IF($B$10 >= 51, 1, 0) -> 0 | D44: =IF($B$17 >= 50, 1, 0) -> 0 | E44: =IF($B$23 >= 45, 1,) -> 0 | F44: =IF($B$29 >= 50, 1,) -> 0 | G44: =IF($B$36 >= 50, 1,) -> 0 | K44: ZI | M44: 35 | N44: =L44/M44 -> 0 | O44: Ocjena | P44: ECTS
A45: 3 | B45: =IF($B$5 >= 62, 1, 0) -> 0 | C45: =IF($B$10 >= 63, 1, 0) -> 0 | D45: =IF($B$17 >= 65, 1, ) -> 0 | E45: =IF($B$23 >= 55, 1, ) -> 0 | F45: =IF($B$29 >= 60, 1,) -> 0 | G45: =IF($B$36 >= 60, 1,) -> 0 | K45: UKUPNO | L45: =SUM(L42:L44) -> 0 | M45: =SUM(M42:M44) -> 100 | N45: =L45/M45 -> 0 | O45: =Y3 -> 0 | P45: =IF(#REF! >1, 2, 0) -> #REF!
A46: 4 | B46: =IF($B$5 >= 75, 1, 0) -> 0 | C46: =IF($B$10 >= 75, 1, 0) -> 0 | D46: =IF($B$17 >= 80, 1, 0) -> 0 | E46: =IF($B$23 >= 70, 1, ) -> 0 | F46: =IF($B$29 >= 75, 1,) -> 0 | G46: =IF($B$36 >= 75, 1,) -> 0
...
